Workbook

Sheet HƯỚNG DẪN
A1: SHAKAIJIN — VIKC 2026 · ĐĂNG KÝ & DỰ TOÁN CHUYẾN ĐI
B3: 1ST VIETNAM INTERNATIONAL KENDO CHAMPIONSHIPS 2026
B4: Giải đấu | C4: 19–22/11/2026
B5: Địa điểm | C5: Trung tâm Hội nghị Quốc tế Vesak, Tam Chúc, Ninh Bình
B6: Hà Nội — giao lưu võ đường | C6: 23–29/11/2026
B7: Đơn vị tổ chức | C7: Liên đoàn Kendo Việt Nam (VKF)
A9: CÁCH SỬ DỤNG
B10: 1. Mở tab ĐĂNG KÝ. Mỗi thành viên điền vào DÒNG CỦA MÌNH.
B11: 2. Chọn Mã thành viên ở cột A — Họ tên, Kyu/Dan, tư cách VKF, SĐT, email sẽ tự điền.
B12: 3. Chọn Trạng thái, đánh dấu Tham gia, nhập Điểm đi, Ngày/Giờ đến-về (dự kiến).
B13: 4. Chọn hạng mục: Thi Dan?, Seminar?, Godo Keiko?, Team-3, Team-5, Giao lưu HN.
B14: 5. Chọn võ đường muốn giao lưu (Yushinkai / Thăng Long / Hà Nội / Yuei — chọn nhiều).
B15: 6. Chọn Loại phòng; admin phân đội ở tab ĐỘI rồi chọn Mã đội.
B16: 7. Nếu có Thi Dan?, điền tab HỒ SƠ VKF.
B17: 8. Xem Chi phí dự kiến (tự tính — Phase 5). Cập nhật Đã thanh toán.
B18: 9. Theo dõi mốc thời gian và chương trình ở tab LỊCH TRÌNH.
A20: QUY ƯỚC MÀU
B21: Vàng | C21: Thành viên tự nhập
B22: Xám | C22: Tự động — KHÔNG sửa
B23: Xanh | C23: Ban tổ chức / admin nhập (CẤU HÌNH, Provider, ĐỘI)
A25: HẠN CHÓT & THANH TOÁN
B26: Hạn đăng ký Kyu/Dan & đội hình | C26: Thứ Ba 20/10/2026
B27: Hạn hoàn thành phí tham dự | C27: 25/10/2026
B28: Tài khoản | C28: Liên đoàn Kendo Việt Nam — BIDV 8680065219
B29: Cú pháp chuyển khoản | C29: Tên đội_1vikc
B30: Email hồ sơ | C30: vikc@vietnamkendo.com · info@kendo.vn
A32: LƯU Ý CHO ADMIN
B33: • Sheet dùng chung: ai có link đều sửa được. Vào Data → Protect sheets and ranges để giới hạn quyền sửa CẤU HÌNH, Provider, ĐỘI, TỔNG QUAN chỉ với tài khoản admin.
B34: • Cột TRUE/FALSE có thể chuyển thành checkbox: chọn vùng → Insert → Checkbox (công thức vẫn chạy).
B35: • Ngày dùng date picker của Google Sheets; giờ nhập HH:MM.
B36: • Sheet này KHÔNG liên kết với 'Shakaijin - member and money'.
B37: • Lưu ý: Khách sạn Tam Chúc (VIKC 19–22) do VKF cung cấp — chọn Loại phòng, không chọn ở Provider. Mục 'Khách sạn Hà Nội' ở Provider chỉ dùng cho chặng Hà Nội (23–29/11).

Sheet THÀNH VIÊN
A1: THÀNH VIÊN — SHAKAIJIN KENDO TEAM
A2: Mã thành viên | B2: Mã VKF | C2: Họ tên | D2: Giới tính | E2: Ngày sinh | F2: Kyu/Dan | G2: Email | H2: SĐT | I2: Thành viên VKF? | J2: Ghi chú
A3: SKJ-198 | B3: 251000156 | C3: Trương Hứa Dân | D3: Nam | E3: 34487 | F3: 4 dan | G3: l3un.kun@gmail.com | H3: 0369252359 | I3: =IF(OR(B3="-",B3=""),"Không","Có")
A4: SKJ-201 | B4: - | C4: Ngô Đình Quốc Tuấn | D4: Nam | F4: 3 dan | I4: =IF(OR(B4="-",B4=""),"Không","Có")
A5: SKJ-023 | B5: 251000150 | C5: Nguyễn Trương Hải Huy | D5: Nam | E5: 37943 | F5: 2 dan | G5: haihuynguyen18112003@gmail.com | H5: 0906986055 | I5: =IF(OR(B5="-",B5=""),"Không","Có")
A6: SKJ-960 | B6: 251000158 | C6: Hoàng Duy | D6: Nam | E6: 36441 | F6: 1 dan | G6: hoangduyno09@gmail.com | H6: 0769743467 | I6: =IF(OR(B6="-",B6=""),"Không","Có")
A7: SKJ-494 | B7: 260600326 | C7: Tăng Hưng Bình | D7: Nam | E7: 36260 | F7: 1 kyu | G7: tanghungbinh104@gmail.com | H7: 0988473159 | I7: =IF(OR(B7="-",B7=""),"Không","Có")
A8: SKJ-275 | B8: 251000154 | C8: Ngô Mai Ngọc Hân | D8: Nữ | E8: 37270 | F8: 1 dan | G8: hanngomaingoc14@gmail.com | H8: 0962273500 | I8: =IF(OR(B8="-",B8=""),"Không","Có")
A9: SKJ-746 | B9: 251000143 | C9: Ngô Quốc Bảo | D9: Nam | E9: 36181 | F9: 1 dan | G9: pandangoo2101@gmail.com | H9: 0907687015 | I9: =IF(OR(B9="-",B9=""),"Không","Có")
A10: SKJ-930 | B10: 251000155 | C10: Nguyễn Võ Huyền Vi | D10: Nữ | E10: 37164 | F10: 1 dan | G10: hvinguyen.309@gmail.com | H10: 0703317105 | I10: =IF(OR(B10="-",B10=""),"Không","Có")
A11: SKJ-281 | B11: 251000144 | C11: Phùng Thanh Nhật Uyên | D11: Nữ | E11: 34415 | F11: 1 dan | G11: ether.sigmata@gmail.com | H11: 0908049049 | I11: =IF(OR(B11="-",B11=""),"Không","Có")
A12: SKJ-826 | B12: 251000168 | C12: Trần Bảo Tín | D12: Nam | E12: 35094 | F12: 1 dan | G12: tbaotin96@gmail.com | H12: 0338620648 | I12: =IF(OR(B12="-",B12=""),"Không","Có")
A13: SKJ-195 | B13: 251000151 | C13: Trần Lê Vĩnh Huy | D13: Nam | E13: 35473 | F13: 1 dan | G13: huytranle13@gmail.com | H13: 0961430298 | I13: =IF(OR(B13="-",B13=""),"Không","Có")
A14: SKJ-619 | B14: 251000163 | C14: Nguyễn Đức Khải | D14: Nam | F14: 1 dan | I14: =IF(OR(B14="-",B14=""),"Không","Có")
A15: SKJ-785 | B15: 251000113 | C15: Nguyễn Thị Bích Liên | D15: Nữ | E15: 32924 | F15: 1 dan | G15: nguyenlien2191@gmail.com | H15: 0343871468 | I15: =IF(OR(B15="-",B15=""),"Không","Có")
A16: SKJ-291 | B16: 251000149 | C16: Nguyễn Thị Ngọc Diễm | D16: Nữ | F16: 1 dan | I16: =IF(OR(B16="-",B16=""),"Không","Có")
A17: SKJ-108 | B17: 251000161 | C17: Đào Duy Khoa | D17: Nam | E17: 35401 | F17: 1 dan | G17: khoadduy@gmail.com | H17: 0911569711 | I17: =IF(OR(B17="-",B17=""),"Không","Có")
A18: SKJ-109 | B18: 260600321 | C18: Nguyễn Thị Cẩm Tú | D18: Nữ | E18: 35577 | F18: - | G18: Nguyen28.w@gmail.com | H18: 0866195026 | I18: =IF(OR(B18="-",B18=""),"Không","Có")
A19: SKJ-088 | B19: 260600322 | C19: Nguyễn Thị Trà My | D19: Nữ | E19: 33725 | F19: - | G19: huixin2688@gmail.com | H19: 0763265388 | I19: =IF(OR(B19="-",B19=""),"Không","Có")
A20: SKJ-036 | B20: 260600325 | C20: Nguyễn Thuý An | D20: Nữ | E20: 38332 | F20: - | G20: alice.anthuynguyen@gmail.com | H20: 0985063466 | I20: =IF(OR(B20="-",B20=""),"Không","Có")
A21: SKJ-074 | C21: Nguyễn Ngọc Hân | D21: Nữ | E21: 37969 | F21: - | G21: nnh14122003@gmail.com | H21: 0903872644 | I21: =IF(OR(B21="-",B21=""),"Không","Có")
A22: SKJ-235 | C22: Hà My Phụng Vỹ | D22: Nữ | F22: - | I22: =IF(OR(B22="-",B22=""),"Không","Có")
A23: SKJ-258 | C23: Lê Vy | D23: Nữ | F23: - | I23: =IF(OR(B23="-",B23=""),"Không","Có")
A24: SKJ-855 | C24: Phạm Ngọc Thuý | D24: Nữ | F24: - | I24: =IF(OR(B24="-",B24=""),"Không","Có")

Sheet CẤU HÌNH
A1: 🔒 CẤU HÌNH (admin) — danh mục, biểu phí, đơn giá
A3: DANH MỤC
A4: Trạng thái | C4: Giới tính | E4: Loại phòng | G4: Bậc Kyu/Dan
A5: Quan tâm | C5: Nam | E5: Phòng đôi (ghép) | G5: -
A6: Tạm xác nhận | C6: Nữ | E6: Phòng ba (ghép) | G6: 6 kyu
A7: Đã xác nhận | E7: Phòng đơn | G7: 5 kyu
A8: Hủy | G8: 4 kyu
G9: 3 kyu
G10: 2 kyu
G11: 1 kyu
G12: 1 dan
G13: 2 dan
G14: 3 dan
G15: 4 dan
G16: 5 dan
G17: 6 dan
G18: 7 dan
G19: 8 dan
A21: BẬC THI KYU/DAN & LỆ PHÍ ĐĂNG KÝ THI
A22: Bậc thi | B22: Phí VKF | C22: Phí không VKF | D22: Ghi chú
A23: 1 kyu | B23: 1000000 | C23: 2000000
A24: 1 dan | B24: 1500000 | C24: 2500000
A25: 2 dan | B25: 2200000 | C25: 4200000
A26: 3 dan | B26: 3000000 | C26: 5000000
A27: 4 dan | B27: 4500000 | C27: 6500000
A28: 5 dan | B28: 6000000 | C28: 8000000
D29: Lệ phí cấp chứng chỉ = 30% lệ phí thi (hoàn lại nếu không đạt)
A30: GÓI THI ĐẤU — THÀNH VIÊN VKF
A31: Loại phòng | B31: 1 nội dung | C31: 2 nội dung | D31: Ghi chú
A32: Phòng đôi (ghép) | B32: 1550000 | C32: 1850000
A33: Phòng ba (ghép) | B33: 1450000 | C33: 1750000
A34: Phòng đơn | B34: 1900000 | C34: 2200000
A36: GÓI THI ĐẤU — KHÔNG PHẢI THÀNH VIÊN VKF
A37: Loại phòng | B37: 1 nội dung | C37: 2 nội dung | D37: Ghi chú
A38: Phòng đôi (ghép) | B38: 1950000 | C38: 2350000
A39: Phòng ba (ghép) | B39: 1850000 | C39: 2250000
A40: Phòng đơn | B40: 2400000 | C40: 2800000
A42: ĐÊM THÊM / NGƯỜI KHÔNG THI ĐẤU — VKF
A43: Loại phòng | B43: Giá/đêm | C43: Ghi chú
A44: Phòng đôi (ghép) | B44: 350000
...

Sheet ĐĂNG KÝ
A1: ĐĂNG KÝ CHUYẾN ĐI — mỗi thành viên điền dòng của mình (thông tin · tham gia · hạng mục · chọn dịch vụ)
A2: Mã thành viên | B2: Họ tên | C2: Kyu/Dan | D2: VKF? | E2: SĐT | F2: Email | G2: Trạng thái | H2: Tham gia? | I2: Điểm đi | J2: Ngày đến | K2: Giờ đến | L2: Ngày về | M2: Giờ về | N2: Đến (datetime) | O2: Về (datetime) | P2: Số đêm | Q2: Số ngày | R2: Thi Dan? | S2: Seminar? | T2: Godo Keiko? | U2: Team-3 | V2: Team-5 | W2: Giao lưu HN | X2: Yushinkai | Y2: Thăng Long | Z2: Hà Nội | AA2: Yuei | AB2: Mã đội | AC2: Loại phòng | AD2: Bạn cùng phòng | AE2: Mã vé MB (FL) | AF2: Mã xe (BUS) | AG2: Mã KS Hà Nội (HTL) | AH2: Gợi ý NCC (auto) | AI2: Ghi chú
A3: SKJ-198 | B3: =IF($A3="","",IFERROR(VLOOKUP($A3,'THÀNH VIÊN'!$A$3:$J$200,3,FALSE),"")) | C3: =IF($A3="","",IFERROR(VLOOKUP($A3,'THÀNH VIÊN'!$A$3:$J$200,6,FALSE),"")) | D3: =IF($A3="","",IFERROR(VLOOKUP($A3,'THÀNH VIÊN'!$A$3:$J$200,9,FALSE),"")) | E3: =IF($A3="","",IFERROR(VLOOKUP($A3,'THÀNH VIÊN'!$A$3:$J$200,8,FALSE),"")) | F3: =IF($A3="","",IFERROR(VLOOKUP($A3,'THÀNH VIÊN'!$A$3:$J$200,7,FALSE),"")) | N3: =IF($J3="","",$J3+IF($K3="",0,$K3)) | O3: =IF($L3="","",$L3+IF($M3="",0,$M3)) | P3: =IF(OR($N3="",$O3=""),"",MAX(0,INT($O3)-INT($N3))) | Q3: =IF(OR($N3="",$O3=""),"",MAX(0,INT($O3)-INT($N3))+1) | AH3: =IF($I3="","",IF(COUNTIF(Provider!$K$5:$K$14,$I3)=0,"—",IF(COUNTIF(Provider!$K$5:$K$14,$I3)=1,INDEX(Provider!$A$5:$A$14,MATCH($I3,Provider!$K$5:$K$14,0)),COUNTIF(Provider!$K$5:$K$14,$I3)&" lựa chọn")))
A4: SKJ-201 | B4: =IF($A4="","",IFERROR(VLOOKUP($A4,'THÀNH VIÊN'!$A$3:$J$200,3,FALSE),"")) | C4: =IF($A4="","",IFERROR(VLOOKUP($A4,'THÀNH VIÊN'!$A$3:$J$200,6,FALSE),"")) | D4: =IF($A4="","",IFERROR(VLOOKUP($A4,'THÀNH VIÊN'!$A$3:$J$200,9,FALSE),"")) | E4: =IF($A4="","",IFERROR(VLOOKUP($A4,'THÀNH VIÊN'!$A$3:$J$200,8,FALSE),"")) | F4: =IF($A4="","",IFERROR(VLOOKUP($A4,'THÀNH VIÊN'!$A$3:$J$200,7,FALSE),"")) | N4: =IF($J4="","",$J4+IF($K4="",0,$K4)) | O4: =IF($L4="","",$L4+IF($M4="",0,$M4)) | P4: =IF(OR($N4="",$O4=""),"",MAX(0,INT($O4)-INT($N4))) | Q4: =IF(OR($N4="",$O4=""),"",MAX(0,INT($O4)-INT($N4))+1) | AH4: =IF($I4="","",IF(COUNTIF(Provider!$K$5:$K$14,$I4)=0,"—",IF(COUNTIF(Provider!$K$5:$K$14,$I4)=1,INDEX(Provider!$A$5:$A$14,MATCH($I4,Provider!$K$5:$K$14,0)),COUNTIF(Provider!$K$5:$K$14,$I4)&" lựa chọn")))
A5: SKJ-023 | B5: =IF($A5="","",IFERROR(VLOOKUP($A5,'THÀNH VIÊN'!$A$3:$J$200,3,FALSE),"")) | C5: =IF($A5="","",IFERROR(VLOOKUP($A5,'THÀNH VIÊN'!$A$3:$J$200,6,FALSE),"")) | D5: =IF($A5="","",IFERROR(VLOOKUP($A5,'THÀNH VIÊN'!$A$3:$J$200,9,FALSE),"")) | E5: =IF($A5="","",IFERROR(VLOOKUP($A5,'THÀNH VIÊN'!$A$3:$J$200,8,FALSE),"")) | F5: =IF($A5="","",IFERROR(VLOOKUP($A5,'THÀNH VIÊN'!$A$3:$J$200,7,FALSE),"")) | N5: =IF($J5="","",$J5+IF($K5="",0,$K5)) | O5: =IF($L5="","",$L5+IF($M5="",0,$M5)) | P5: =IF(OR($N5="",$O5=""),"",MAX(0,INT($O5)-INT($N5))) | Q5: =IF(OR($N5="",$O5=""),"",MAX(0,INT($O5)-INT($N5))+1) | AH5: =IF($I5="","",IF(COUNTIF(Provider!$K$5:$K$14,$I5)=0,"—",IF(COUNTIF(Provider!$K$5:$K$14,$I5)=1,INDEX(Provider!$A$5:$A$14,MATCH($I5,Provider!$K$5:$K$14,0)),COUNTIF(Provider!$K$5:$K$14,$I5)&" lựa chọn")))
A6: SKJ-960 | B6: =IF($A6="","",IFERROR(VLOOKUP($A6,'THÀNH VIÊN'!$A$3:$J$200,3,FALSE),"")) | C6: =IF($A6="","",IFERROR(VLOOKUP($A6,'THÀNH VIÊN'!$A$3:$J$200,6,FALSE),"")) | D6: =IF($A6="","",IFERROR(VLOOKUP($A6,'THÀNH VIÊN'!$A$3:$J$200,9,FALSE),"")) | E6: =IF($A6="","",IFERROR(VLOOKUP($A6,'THÀNH VIÊN'!$A$3:$J$200,8,FALSE),"")) | F6: =IF($A6="","",IFERROR(VLOOKUP($A6,'THÀNH VIÊN'!$A$3:$J$200,7,FALSE),"")) | N6: =IF($J6="","",$J6+IF($K6="",0,$K6)) | O6: =IF($L6="","",$L6+IF($M6="",0,$M6)) | P6: =IF(OR($N6="",$O6=""),"",MAX(0,INT($O6)-INT($N6))) | Q6: =IF(OR($N6="",$O6=""),"",MAX(0,INT($O6)-INT($N6))+1) | AH6: =IF($I6="","",IF(COUNTIF(Provider!$K$5:$K$14,$I6)=0,"—",IF(COUNTIF(Provider!$K$5:$K$14,$I6)=1,INDEX(Provider!$A$5:$A$14,MATCH($I6,Provider!$K$5:$K$14,0)),COUNTIF(Provider!$K$5:$K$14,$I6)&" lựa chọn")))
A7: SKJ-494 | B7: =IF($A7="","",IFERROR(VLOOKUP($A7,'THÀNH VIÊN'!$A$3:$J$200,3,FALSE),"")) | C7: =IF($A7="","",IFERROR(VLOOKUP($A7,'THÀNH VIÊN'!$A$3:$J$200,6,FALSE),"")) | D7: =IF($A7="","",IFERROR(VLOOKUP($A7,'THÀNH VIÊN'!$A$3:$J$200,9,FALSE),"")) | E7: =IF($A7="","",IFERROR(VLOOKUP($A7,'THÀNH VIÊN'!$A$3:$J$200,8,FALSE),"")) | F7: =IF($A7="","",IFERROR(VLOOKUP($A7,'THÀNH VIÊN'!$A$3:$J$200,7,FALSE),"")) | N7: =IF($J7="","",$J7+IF($K7="",0,$K7)) | O7: =IF($L7="","",$L7+IF($M7="",0,$M7)) | P7: =IF(OR($N7="",$O7=""),"",MAX(0,INT($O7)-INT($N7))) | Q7: =IF(OR($N7="",$O7=""),"",MAX(0,INT($O7)-INT($N7))+1) | AH7: =IF($I7="","",IF(COUNTIF(Provider!$K$5:$K$14,$I7)=0,"—",IF(COUNTIF(Provider!$K$5:$K$14,$I7)=1,INDEX(Provider!$A$5:$A$14,MATCH($I7,Provider!$K$5:$K$14,0)),COUNTIF(Provider!$K$5:$K$14,$I7)&" lựa chọn")))
A8: SKJ-275 | B8: =IF($A8="","",IFERROR(VLOOKUP($A8,'THÀNH VIÊN'!$A$3:$J$200,3,FALSE),"")) | C8: =IF($A8="","",IFERROR(VLOOKUP($A8,'THÀNH VIÊN'!$A$3:$J$200,6,FALSE),"")) | D8: =IF($A8="","",IFERROR(VLOOKUP($A8,'THÀNH VIÊN'!$A$3:$J$200,9,FALSE),"")) | E8: =IF($A8="","",IFERROR(VLOOKUP($A8,'THÀNH VIÊN'!$A$3:$J$200,8,FALSE),"")) | F8: =IF($A8="","",IFERROR(VLOOKUP($A8,'THÀNH VIÊN'!$A$3:$J$200,7,FALSE),"")) | N8: =IF($J8="","",$J8+IF($K8="",0,$K8)) | O8: =IF($L8="","",$L8+IF($M8="",0,$M8)) | P8: =IF(OR($N8="",$O8=""),"",MAX(0,INT($O8)-INT($N8))) | Q8: =IF(OR($N8="",$O8=""),"",MAX(0,INT($O8)-INT($N8))+1) | AH8: =IF($I8="","",IF(COUNTIF(Provider!$K$5:$K$14,$I8)=0,"—",IF(COUNTIF(Provider!$K$5:$K$14,$I8)=1,INDEX(Provider!$A$5:$A$14,MATCH($I8,Provider!$K$5:$K$14,0)),COUNTIF(Provider!$K$5:$K$14,$I8)&" lựa chọn")))
A9: SKJ-746 | B9: =IF($A9="","",IFERROR(VLOOKUP($A9,'THÀNH VIÊN'!$A$3:$J$200,3,FALSE),"")) | C9: =IF($A9="","",IFERROR(VLOOKUP($A9,'THÀNH VIÊN'!$A$3:$J$200,6,FALSE),"")) | D9: =IF($A9="","",IFERROR(VLOOKUP($A9,'THÀNH VIÊN'!$A$3:$J$200,9,FALSE),"")) | E9: =IF($A9="","",IFERROR(VLOOKUP($A9,'THÀNH VIÊN'!$A$3:$J$200,8,FALSE),"")) | F9: =IF($A9="","",IFERROR(VLOOKUP($A9,'THÀNH VIÊN'!$A$3:$J$200,7,FALSE),"")) | N9: =IF($J9="","",$J9+IF($K9="",0,$K9)) | O9: =IF($L9="","",$L9+IF($M9="",0,$M9)) | P9: =IF(OR($N9="",$O9=""),"",MAX(0,INT($O9)-INT($N9))) | Q9: =IF(OR($N9="",$O9=""),"",MAX(0,INT($O9)-INT($N9))+1) | AH9: =IF($I9="","",IF(COUNTIF(Provider!$K$5:$K$14,$I9)=0,"—",IF(COUNTIF(Provider!$K$5:$K$14,$I9)=1,INDEX(Provider!$A$5:$A$14,MATCH($I9,Provider!$K$5:$K$14,0)),COUNTIF(Provider!$K$5:$K$14,$I9)&" lựa chọn")))
A10: SKJ-930 | B10: =IF($A10="","",IFERROR(VLOOKUP($A10,'THÀNH VIÊN'!$A$3:$J$200,3,FALSE),"")) | C10: =IF($A10="","",IFERROR(VLOOKUP($A10,'THÀNH VIÊN'!$A$3:$J$200,6,FALSE),"")) | D10: =IF($A10="","",IFERROR(VLOOKUP($A10,'THÀNH VIÊN'!$A$3:$J$200,9,FALSE),"")) | E10: =IF($A10="","",IFERROR(VLOOKUP($A10,'THÀNH VIÊN'!$A$3:$J$200,8,FALSE),"")) | F10: =IF($A10="","",IFERROR(VLOOKUP($A10,'THÀNH VIÊN'!$A$3:$J$200,7,FALSE),"")) | N10: =IF($J10="","",$J10+IF($K10="",0,$K10)) | O10: =IF($L10="","",$L10+IF($M10="",0,$M10)) | P10: =IF(OR($N10="",$O10=""),"",MAX(0,INT($O10)-INT($N10))) | Q10: =IF(OR($N10="",$O10=""),"",MAX(0,INT($O10)-INT($N10))+1) | AH10: =IF($I10="","",IF(COUNTIF(Provider!$K$5:$K$14,$I10)=0,"—",IF(COUNTIF(Provider!$K$5:$K$14,$I10)=1,INDEX(Provider!$A$5:$A$14,MATCH($I10,Provider!$K$5:$K$14,0)),COUNTIF(Provider!$K$5:$K$14,$I10)&" lựa chọn")))
A11: SKJ-281 | B11: =IF($A11="","",IFERROR(VLOOKUP($A11,'THÀNH VIÊN'!$A$3:$J$200,3,FALSE),"")) | C11: =IF($A11="","",IFERROR(VLOOKUP($A11,'THÀNH VIÊN'!$A$3:$J$200,6,FALSE),"")) | D11: =IF($A11="","",IFERROR(VLOOKUP($A11,'THÀNH VIÊN'!$A$3:$J$200,9,FALSE),"")) | E11: =IF($A11="","",IFERROR(VLOOKUP($A11,'THÀNH VIÊN'!$A$3:$J$200,8,FALSE),"")) | F11: =IF($A11="","",IFERROR(VLOOKUP($A11,'THÀNH VIÊN'!$A$3:$J$200,7,FALSE),"")) | N11: =IF($J11="","",$J11+IF($K11="",0,$K11)) | O11: =IF($L11="","",$L11+IF($M11="",0,$M11)) | P11: =IF(OR($N11="",$O11=""),"",MAX(0,INT($O11)-INT($N11))) | Q11: =IF(OR($N11="",$O11=""),"",MAX(0,INT($O11)-INT($N11))+1) | AH11: =IF($I11="","",IF(COUNTIF(Provider!$K$5:$K$14,$I11)=0,"—",IF(COUNTIF(Provider!$K$5:$K$14,$I11)=1,INDEX(Provider!$A$5:$A$14,MATCH($I11,Provider!$K$5:$K$14,0)),COUNTIF(Provider!$K$5:$K$14,$I11)&" lựa chọn")))
A12: SKJ-826 | B12: =IF($A12="","",IFERROR(VLOOKUP($A12,'THÀNH VIÊN'!$A$3:$J$200,3,FALSE),"")) | C12: =IF($A12="","",IFERROR(VLOOKUP($A12,'THÀNH VIÊN'!$A$3:$J$200,6,FALSE),"")) | D12: =IF($A12="","",IFERROR(VLOOKUP($A12,'THÀNH VIÊN'!$A$3:$J$200,9,FALSE),"")) | E12: =IF($A12="","",IFERROR(VLOOKUP($A12,'THÀNH VIÊN'!$A$3:$J$200,8,FALSE),"")) | F12: =IF($A12="","",IFERROR(VLOOKUP($A12,'THÀNH VIÊN'!$A$3:$J$200,7,FALSE),"")) | N12: =IF($J12="","",$J12+IF($K12="",0,$K12)) | O12: =IF($L12="","",$L12+IF($M12="",0,$M12)) | P12: =IF(OR($N12="",$O12=""),"",MAX(0,INT($O12)-INT($N12))) | Q12: =IF(OR($N12="",$O12=""),"",MAX(0,INT($O12)-INT($N12))+1) | AH12: =IF($I12="","",IF(COUNTIF(Provider!$K$5:$K$14,$I12)=0,"—",IF(COUNTIF(Provider!$K$5:$K$14,$I12)=1,INDEX(Provider!$A$5:$A$14,MATCH($I12,Provider!$K$5:$K$14,0)),COUNTIF(Provider!$K$5:$K$14,$I12)&" lựa chọn")))
A13: SKJ-195 | B13: =IF($A13="","",IFERROR(VLOOKUP($A13,'THÀNH VIÊN'!$A$3:$J$200,3,FALSE),"")) | C13: =IF($A13="","",IFERROR(VLOOKUP($A13,'THÀNH VIÊN'!$A$3:$J$200,6,FALSE),"")) | D13: =IF($A13="","",IFERROR(VLOOKUP($A13,'THÀNH VIÊN'!$A$3:$J$200,9,FALSE),"")) | E13: =IF($A13="","",IFERROR(VLOOKUP($A13,'THÀNH VIÊN'!$A$3:$J$200,8,FALSE),"")) | F13: =IF($A13="","",IFERROR(VLOOKUP($A13,'THÀNH VIÊN'!$A$3:$J$200,7,FALSE),"")) | N13: =IF($J13="","",$J13+IF($K13="",0,$K13)) | O13: =IF($L13="","",$L13+IF($M13="",0,$M13)) | P13: =IF(OR($N13="",$O13=""),"",MAX(0,INT($O13)-INT($N13))) | Q13: =IF(OR($N13="",$O13=""),"",MAX(0,INT($O13)-INT($N13))+1) | AH13: =IF($I13="","",IF(COUNTIF(Provider!$K$5:$K$14,$I13)=0,"—",IF(COUNTIF(Provider!$K$5:$K$14,$I13)=1,INDEX(Provider!$A$5:$A$14,MATCH($I13,Provider!$K$5:$K$14,0)),COUNTIF(Provider!$K$5:$K$14,$I13)&" lựa chọn")))
A14: SKJ-619 | B14: =IF($A14="","",IFERROR(VLOOKUP($A14,'THÀNH VIÊN'!$A$3:$J$200,3,FALSE),"")) | C14: =IF($A14="","",IFERROR(VLOOKUP($A14,'THÀNH VIÊN'!$A$3:$J$200,6,FALSE),"")) | D14: =IF($A14="","",IFERROR(VLOOKUP($A14,'THÀNH VIÊN'!$A$3:$J$200,9,FALSE),"")) | E14: =IF($A14="","",IFERROR(VLOOKUP($A14,'THÀNH VIÊN'!$A$3:$J$200,8,FALSE),"")) | F14: =IF($A14="","",IFERROR(VLOOKUP($A14,'THÀNH VIÊN'!$A$3:$J$200,7,FALSE),"")) | N14: =IF($J14="","",$J14+IF($K14="",0,$K14)) | O14: =IF($L14="","",$L14+IF($M14="",0,$M14)) | P14: =IF(OR($N14="",$O14=""),"",MAX(0,INT($O14)-INT($N14))) | Q14: =IF(OR($N14="",$O14=""),"",MAX(0,INT($O14)-INT($N14))+1) | AH14: =IF($I14="","",IF(COUNTIF(Provider!$K$5:$K$14,$I14)=0,"—",IF(COUNTIF(Provider!$K$5:$K$14,$I14)=1,INDEX(Provider!$A$5:$A$14,MATCH($I14,Provider!$K$5:$K$14,0)),COUNTIF(Provider!$K$5:$K$14,$I14)&" lựa chọn")))
... A24: SKJ-855 | B24: =IF($A24="","",IFERROR(VLOOKUP($A24,'THÀNH VIÊN'!$A$3:$J$200,3,FALSE),"")) | C24: =IF($A24="","",IFERROR(VLOOKUP($A24,'THÀNH VIÊN'!$A$3:$J$200,6,FALSE),"")) | D24: =IF($A24="","",IFERROR(VLOOKUP($A24,'THÀNH VIÊN'!$A$3:$J$200,9,FALSE),"")) | E24: =IF($A24="","",IFERROR(VLOOKUP($A24,'THÀNH VIÊN'!$A$3:$J$200,8,FALSE),"")) | F24: =IF($A24="","",IFERROR(VLOOKUP($A24,'THÀNH VIÊN'!$A$3:$J$200,7,FALSE),"")) | N24: =IF($J24="","",$J24+IF($K24="",0,$K24)) | O24: =IF($L24="","",$L24+IF($M24="",0,$M24)) | P24: =IF(OR($N24="",$O24=""),"",MAX(0,INT($O24)-INT($N24))) | Q24: =IF(OR($N24="",$O24=""),"",MAX(0,INT($O24)-INT($N24))+1) | AH24: =IF($I24="","",IF(COUNTIF(Provider!$K$5:$K$14,$I24)=0,"—",IF(COUNTIF(Provider!$K$5:$K$14,$I24)=1,INDEX(Provider!$A$5:$A$14,MATCH($I24,Provider!$K$5:$K$14,0)),COUNTIF(Provider!$K$5:$K$14,$I24)&" lựa chọn")))
B25: =IF($A25="","",IFERROR(VLOOKUP($A25,'THÀNH VIÊN'!$A$3:$J$200,3,FALSE),"")) | C25: =IF($A25="","",IFERROR(VLOOKUP($A25,'THÀNH VIÊN'!$A$3:$J$200,6,FALSE),"")) | D25: =IF($A25="","",IFERROR(VLOOKUP($A25,'THÀNH VIÊN'!$A$3:$J$200,9,FALSE),"")) | E25: =IF($A25="","",IFERROR(VLOOKUP($A25,'THÀNH VIÊN'!$A$3:$J$200,8,FALSE),"")) | F25: =IF($A25="","",IFERROR(VLOOKUP($A25,'THÀNH VIÊN'!$A$3:$J$200,7,FALSE),"")) | N25: =IF($J25="","",$J25+IF($K25="",0,$K25)) | O25: =IF($L25="","",$L25+IF($M25="",0,$M25)) | P25: =IF(OR($N25="",$O25=""),"",MAX(0,INT($O25)-INT($N25))) | Q25: =IF(OR($N25="",$O25=""),"",MAX(0,INT($O25)-INT($N25))+1) | AH25: =IF($I25="","",IF(COUNTIF(Provider!$K$5:$K$14,$I25)=0,"—",IF(COUNTIF(Provider!$K$5:$K$14,$I25)=1,INDEX(Provider!$A$5:$A$14,MATCH($I25,Provider!$K$5:$K$14,0)),COUNTIF(Provider!$K$5:$K$14,$I25)&" lựa chọn")))
B26: =IF($A26="","",IFERROR(VLOOKUP($A26,'THÀNH VIÊN'!$A$3:$J$200,3,FALSE),"")) | C26: =IF($A26="","",IFERROR(VLOOKUP($A26,'THÀNH VIÊN'!$A$3:$J$200,6,FALSE),"")) | D26: =IF($A26="","",IFERROR(VLOOKUP($A26,'THÀNH VIÊN'!$A$3:$J$200,9,FALSE),"")) | E26: =IF($A26="","",IFERROR(VLOOKUP($A26,'THÀNH VIÊN'!$A$3:$J$200,8,FALSE),"")) | F26: =IF($A26="","",IFERROR(VLOOKUP($A26,'THÀNH VIÊN'!$A$3:$J$200,7,FALSE),"")) | N26: =IF($J26="","",$J26+IF($K26="",0,$K26)) | O26: =IF($L26="","",$L26+IF($M26="",0,$M26)) | P26: =IF(OR($N26="",$O26=""),"",MAX(0,INT($O26)-INT($N26))) | Q26: =IF(OR($N26="",$O26=""),"",MAX(0,INT($O26)-INT($N26))+1) | AH26: =IF($I26="","",IF(COUNTIF(Provider!$K$5:$K$14,$I26)=0,"—",IF(COUNTIF(Provider!$K$5:$K$14,$I26)=1,INDEX(Provider!$A$5:$A$14,MATCH($I26,Provider!$K$5:$K$14,0)),COUNTIF(Provider!$K$5:$K$14,$I26)&" lựa chọn")))
B27: =IF($A27="","",IFERROR(VLOOKUP($A27,'THÀNH VIÊN'!$A$3:$J$200,3,FALSE),"")) | C27: =IF($A27="","",IFERROR(VLOOKUP($A27,'THÀNH VIÊN'!$A$3:$J$200,6,FALSE),"")) | D27: =IF($A27="","",IFERROR(VLOOKUP($A27,'THÀNH VIÊN'!$A$3:$J$200,9,FALSE),"")) | E27: =IF($A27="","",IFERROR(VLOOKUP($A27,'THÀNH VIÊN'!$A$3:$J$200,8,FALSE),"")) | F27: =IF($A27="","",IFERROR(VLOOKUP($A27,'THÀNH VIÊN'!$A$3:$J$200,7,FALSE),"")) | N27: =IF($J27="","",$J27+IF($K27="",0,$K27)) | O27: =IF($L27="","",$L27+IF($M27="",0,$M27)) | P27: =IF(OR($N27="",$O27=""),"",MAX(0,INT($O27)-INT($N27))) | Q27: =IF(OR($N27="",$O27=""),"",MAX(0,INT($O27)-INT($N27))+1) | AH27: =IF($I27="","",IF(COUNTIF(Provider!$K$5:$K$14,$I27)=0,"—",IF(COUNTIF(Provider!$K$5:$K$14,$I27)=1,INDEX(Provider!$A$5:$A$14,MATCH($I27,Provider!$K$5:$K$14,0)),COUNTIF(Provider!$K$5:$K$14,$I27)&" lựa chọn")))
B28: =IF($A28="","",IFERROR(VLOOKUP($A28,'THÀNH VIÊN'!$A$3:$J$200,3,FALSE),"")) | C28: =IF($A28="","",IFERROR(VLOOKUP($A28,'THÀNH VIÊN'!$A$3:$J$200,6,FALSE),"")) | D28: =IF($A28="","",IFERROR(VLOOKUP($A28,'THÀNH VIÊN'!$A$3:$J$200,9,FALSE),"")) | E28: =IF($A28="","",IFERROR(VLOOKUP($A28,'THÀNH VIÊN'!$A$3:$J$200,8,FALSE),"")) | F28: =IF($A28="","",IFERROR(VLOOKUP($A28,'THÀNH VIÊN'!$A$3:$J$200,7,FALSE),"")) | N28: =IF($J28="","",$J28+IF($K28="",0,$K28)) | O28: =IF($L28="","",$L28+IF($M28="",0,$M28)) | P28: =IF(OR($N28="",$O28=""),"",MAX(0,INT($O28)-INT($N28))) | Q28: =IF(OR($N28="",$O28=""),"",MAX(0,INT($O28)-INT($N28))+1) | AH28: =IF($I28="","",IF(COUNTIF(Provider!$K$5:$K$14,$I28)=0,"—",IF(COUNTIF(Provider!$K$5:$K$14,$I28)=1,INDEX(Provider!$A$5:$A$14,MATCH($I28,Provider!$K$5:$K$14,0)),COUNTIF(Provider!$K$5:$K$14,$I28)&" lựa chọn")))
B29: =IF($A29="","",IFERROR(VLOOKUP($A29,'THÀNH VIÊN'!$A$3:$J$200,3,FALSE),"")) | C29: =IF($A29="","",IFERROR(VLOOKUP($A29,'THÀNH VIÊN'!$A$3:$J$200,6,FALSE),"")) | D29: =IF($A29="","",IFERROR(VLOOKUP($A29,'THÀNH VIÊN'!$A$3:$J$200,9,FALSE),"")) | E29: =IF($A29="","",IFERROR(VLOOKUP($A29,'THÀNH VIÊN'!$A$3:$J$200,8,FALSE),"")) | F29: =IF($A29="","",IFERROR(VLOOKUP($A29,'THÀNH VIÊN'!$A$3:$J$200,7,FALSE),"")) | N29: =IF($J29="","",$J29+IF($K29="",0,$K29)) | O29: =IF($L29="","",$L29+IF($M29="",0,$M29)) | P29: =IF(OR($N29="",$O29=""),"",MAX(0,INT($O29)-INT($N29))) | Q29: =IF(OR($N29="",$O29=""),"",MAX(0,INT($O29)-INT($N29))+1) | AH29: =IF($I29="","",IF(COUNTIF(Provider!$K$5:$K$14,$I29)=0,"—",IF(COUNTIF(Provider!$K$5:$K$14,$I29)=1,INDEX(Provider!$A$5:$A$14,MATCH($I29,Provider!$K$5:$K$14,0)),COUNTIF(Provider!$K$5:$K$14,$I29)&" lựa chọn")))
B30: =IF($A30="","",IFERROR(VLOOKUP($A30,'THÀNH VIÊN'!$A$3:$J$200,3,FALSE),"")) | C30: =IF($A30="","",IFERROR(VLOOKUP($A30,'THÀNH VIÊN'!$A$3:$J$200,6,FALSE),"")) | D30: =IF($A30="","",IFERROR(VLOOKUP($A30,'THÀNH VIÊN'!$A$3:$J$200,9,FALSE),"")) | E30: =IF($A30="","",IFERROR(VLOOKUP($A30,'THÀNH VIÊN'!$A$3:$J$200,8,FALSE),"")) | F30: =IF($A30="","",IFERROR(VLOOKUP($A30,'THÀNH VIÊN'!$A$3:$J$200,7,FALSE),"")) | N30: =IF($J30="","",$J30+IF($K30="",0,$K30)) | O30: =IF($L30="","",$L30+IF($M30="",0,$M30)) | P30: =IF(OR($N30="",$O30=""),"",MAX(0,INT($O30)-INT($N30))) | Q30: =IF(OR($N30="",$O30=""),"",MAX(0,INT($O30)-INT($N30))+1) | AH30: =IF($I30="","",IF(COUNTIF(Provider!$K$5:$K$14,$I30)=0,"—",IF(COUNTIF(Provider!$K$5:$K$14,$I30)=1,INDEX(Provider!$A$5:$A$14,MATCH($I30,Provider!$K$5:$K$14,0)),COUNTIF(Provider!$K$5:$K$14,$I30)&" lựa chọn")))
B31: =IF($A31="","",IFERROR(VLOOKUP($A31,'THÀNH VIÊN'!$A$3:$J$200,3,FALSE),"")) | C31: =IF($A31="","",IFERROR(VLOOKUP($A31,'THÀNH VIÊN'!$A$3:$J$200,6,FALSE),"")) | D31: =IF($A31="","",IFERROR(VLOOKUP($A31,'THÀNH VIÊN'!$A$3:$J$200,9,FALSE),"")) | E31: =IF($A31="","",IFERROR(VLOOKUP($A31,'THÀNH VIÊN'!$A$3:$J$200,8,FALSE),"")) | F31: =IF($A31="","",IFERROR(VLOOKUP($A31,'THÀNH VIÊN'!$A$3:$J$200,7,FALSE),"")) | N31: =IF($J31="","",$J31+IF($K31="",0,$K31)) | O31: =IF($L31="","",$L31+IF($M31="",0,$M31)) | P31: =IF(OR($N31="",$O31=""),"",MAX(0,INT($O31)-INT($N31))) | Q31: =IF(OR($N31="",$O31=""),"",MAX(0,INT($O31)-INT($N31))+1) | AH31: =IF($I31="","",IF(COUNTIF(Provider!$K$5:$K$14,$I31)=0,"—",IF(COUNTIF(Provider!$K$5:$K$14,$I31)=1,INDEX(Provider!$A$5:$A$14,MATCH($I31,Provider!$K$5:$K$14,0)),COUNTIF(Provider!$K$5:$K$14,$I31)&" lựa chọn")))
B32: =IF($A32="","",IFERROR(VLOOKUP($A32,'THÀNH VIÊN'!$A$3:$J$200,3,FALSE),"")) | C32: =IF($A32="","",IFERROR(VLOOKUP($A32,'THÀNH VIÊN'!$A$3:$J$200,6,FALSE),"")) | D32: =IF($A32="","",IFERROR(VLOOKUP($A32,'THÀNH VIÊN'!$A$3:$J$200,9,FALSE),"")) | E32: =IF($A32="","",IFERROR(VLOOKUP($A32,'THÀNH VIÊN'!$A$3:$J$200,8,FALSE),"")) | F32: =IF($A32="","",IFERROR(VLOOKUP($A32,'THÀNH VIÊN'!$A$3:$J$200,7,FALSE),"")) | N32: =IF($J32="","",$J32+IF($K32="",0,$K32)) | O32: =IF($L32="","",$L32+IF($M32="",0,$M32)) | P32: =IF(OR($N32="",$O32=""),"",MAX(0,INT($O32)-INT($N32))) | Q32: =IF(OR($N32="",$O32=""),"",MAX(0,INT($O32)-INT($N32))+1) | AH32: =IF($I32="","",IF(COUNTIF(Provider!$K$5:$K$14,$I32)=0,"—",IF(COUNTIF(Provider!$K$5:$K$14,$I32)=1,INDEX(Provider!$A$5:$A$14,MATCH($I32,Provider!$K$5:$K$14,0)),COUNTIF(Provider!$K$5:$K$14,$I32)&" lựa chọn")))
B33: =IF($A33="","",IFERROR(VLOOKUP($A33,'THÀNH VIÊN'!$A$3:$J$200,3,FALSE),"")) | C33: =IF($A33="","",IFERROR(VLOOKUP($A33,'THÀNH VIÊN'!$A$3:$J$200,6,FALSE),"")) | D33: =IF($A33="","",IFERROR(VLOOKUP($A33,'THÀNH VIÊN'!$A$3:$J$200,9,FALSE),"")) | E33: =IF($A33="","",IFERROR(VLOOKUP($A33,'THÀNH VIÊN'!$A$3:$J$200,8,FALSE),"")) | F33: =IF($A33="","",IFERROR(VLOOKUP($A33,'THÀNH VIÊN'!$A$3:$J$200,7,FALSE),"")) | N33: =IF($J33="","",$J33+IF($K33="",0,$K33)) | O33: =IF($L33="","",$L33+IF($M33="",0,$M33)) | P33: =IF(OR($N33="",$O33=""),"",MAX(0,INT($O33)-INT($N33))) | Q33: =IF(OR($N33="",$O33=""),"",MAX(0,INT($O33)-INT($N33))+1) | AH33: =IF($I33="","",IF(COUNTIF(Provider!$K$5:$K$14,$I33)=0,"—",IF(COUNTIF(Provider!$K$5:$K$14,$I33)=1,INDEX(Provider!$A$5:$A$14,MATCH($I33,Provider!$K$5:$K$14,0)),COUNTIF(Provider!$K$5:$K$14,$I33)&" lựa chọn")))
B34: =IF($A34="","",IFERROR(VLOOKUP($A34,'THÀNH VIÊN'!$A$3:$J$200,3,FALSE),"")) | C34: =IF($A34="","",IFERROR(VLOOKUP($A34,'THÀNH VIÊN'!$A$3:$J$200,6,FALSE),"")) | D34: =IF($A34="","",IFERROR(VLOOKUP($A34,'THÀNH VIÊN'!$A$3:$J$200,9,FALSE),"")) | E34: =IF($A34="","",IFERROR(VLOOKUP($A34,'THÀNH VIÊN'!$A$3:$J$200,8,FALSE),"")) | F34: =IF($A34="","",IFERROR(VLOOKUP($A34,'THÀNH VIÊN'!$A$3:$J$200,7,FALSE),"")) | N34: =IF($J34="","",$J34+IF($K34="",0,$K34)) | O34: =IF($L34="","",$L34+IF($M34="",0,$M34)) | P34: =IF(OR($N34="",$O34=""),"",MAX(0,INT($O34)-INT($N34))) | Q34: =IF(OR($N34="",$O34=""),"",MAX(0,INT($O34)-INT($N34))+1) | AH34: =IF($I34="","",IF(COUNTIF(Provider!$K$5:$K$14,$I34)=0,"—",IF(COUNTIF(Provider!$K$5:$K$14,$I34)=1,INDEX(Provider!$A$5:$A$14,MATCH($I34,Provider!$K$5:$K$14,0)),COUNTIF(Provider!$K$5:$K$14,$I34)&" lựa chọn")))
B35: =IF($A35="","",IFERROR(VLOOKUP($A35,'THÀNH VIÊN'!$A$3:$J$200,3,FALSE),"")) | C35: =IF($A35="","",IFERROR(VLOOKUP($A35,'THÀNH VIÊN'!$A$3:$J$200,6,FALSE),"")) | D35: =IF($A35="","",IFERROR(VLOOKUP($A35,'THÀNH VIÊN'!$A$3:$J$200,9,FALSE),"")) | E35: =IF($A35="","",IFERROR(VLOOKUP($A35,'THÀNH VIÊN'!$A$3:$J$200,8,FALSE),"")) | F35: =IF($A35="","",IFERROR(VLOOKUP($A35,'THÀNH VIÊN'!$A$3:$J$200,7,FALSE),"")) | N35: =IF($J35="","",$J35+IF($K35="",0,$K35)) | O35: =IF($L35="","",$L35+IF($M35="",0,$M35)) | P35: =IF(OR($N35="",$O35=""),"",MAX(0,INT($O35)-INT($N35))) | Q35: =IF(OR($N35="",$O35=""),"",MAX(0,INT($O35)-INT($N35))+1) | AH35: =IF($I35="","",IF(COUNTIF(Provider!$K$5:$K$14,$I35)=0,"—",IF(COUNTIF(Provider!$K$5:$K$14,$I35)=1,INDEX(Provider!$A$5:$A$14,MATCH($I35,Provider!$K$5:$K$14,0)),COUNTIF(Provider!$K$5:$K$14,$I35)&" lựa chọn")))
B36: =IF($A36="","",IFERROR(VLOOKUP($A36,'THÀNH VIÊN'!$A$3:$J$200,3,FALSE),"")) | C36: =IF($A36="","",IFERROR(VLOOKUP($A36,'THÀNH VIÊN'!$A$3:$J$200,6,FALSE),"")) | D36: =IF($A36="","",IFERROR(VLOOKUP($A36,'THÀNH VIÊN'!$A$3:$J$200,9,FALSE),"")) | E36: =IF($A36="","",IFERROR(VLOOKUP($A36,'THÀNH VIÊN'!$A$3:$J$200,8,FALSE),"")) | F36: =IF($A36="","",IFERROR(VLOOKUP($A36,'THÀNH VIÊN'!$A$3:$J$200,7,FALSE),"")) | N36: =IF($J36="","",$J36+IF($K36="",0,$K36)) | O36: =IF($L36="","",$L36+IF($M36="",0,$M36)) | P36: =IF(OR($N36="",$O36=""),"",MAX(0,INT($O36)-INT($N36))) | Q36: =IF(OR($N36="",$O36=""),"",MAX(0,INT($O36)-INT($N36))+1) | AH36: =IF($I36="","",IF(COUNTIF(Provider!$K$5:$K$14,$I36)=0,"—",IF(COUNTIF(Provider!$K$5:$K$14,$I36)=1,INDEX(Provider!$A$5:$A$14,MATCH($I36,Provider!$K$5:$K$14,0)),COUNTIF(Provider!$K$5:$K$14,$I36)&" lựa chọn")))
... B40: =IF($A40="","",IFERROR(VLOOKUP($A40,'THÀNH VIÊN'!$A$3:$J$200,3,FALSE),"")) | C40: =IF($A40="","",IFERROR(VLOOKUP($A40,'THÀNH VIÊN'!$A$3:$J$200,6,FALSE),"")) | D40: =IF($A40="","",IFERROR(VLOOKUP($A40,'THÀNH VIÊN'!$A$3:$J$200,9,FALSE),"")) | E40: =IF($A40="","",IFERROR(VLOOKUP($A40,'THÀNH VIÊN'!$A$3:$J$200,8,FALSE),"")) | F40: =IF($A40="","",IFERROR(VLOOKUP($A40,'THÀNH VIÊN'!$A$3:$J$200,7,FALSE),"")) | N40: =IF($J40="","",$J40+IF($K40="",0,$K40)) | O40: =IF($L40="","",$L40+IF($M40="",0,$M40)) | P40: =IF(OR($N40="",$O40=""),"",MAX(0,INT($O40)-INT($N40))) | Q40: =IF(OR($N40="",$O40=""),"",MAX(0,INT($O40)-INT($N40))+1) | AH40: =IF($I40="","",IF(COUNTIF(Provider!$K$5:$K$14,$I40)=0,"—",IF(COUNTIF(Provider!$K$5:$K$14,$I40)=1,INDEX(Provider!$A$5:$A$14,MATCH($I40,Provider!$K$5:$K$14,0)),COUNTIF(Provider!$K$5:$K$14,$I40)&" lựa chọn")))

Sheet HỒ SƠ VKF
A1: HỒ SƠ VKF — chỉ hiển thị thành viên có 'Thi Dan?' ở tab ĐĂNG KÝ
A2: Mã thành viên | B2: Họ tên | C2: Họ tên Latin (IN HOA) | D2: Dùng tên Latin trên chứng nhận? | E2: Họ tên chữ Hán (Kanji) | F2: Dùng Kanji trên chứng nhận? | G2: CCCD / Hộ chiếu | H2: Quốc tịch | I2: Ngày sinh | J2: Giới tính | K2: SĐT | L2: Email | M2: Địa chỉ | N2: Nghề nghiệp | O2: Tên CLB | P2: Trình độ hiện tại | Q2: Nơi cấp bằng hiện tại | R2: Ngày cấp | S2: Kyu/Dan đăng ký thi | T2: Địa chỉ nhận bằng | U2: Xác nhận của CLB | V2: Ghi chú
A3: =IF('ĐĂNG KÝ'!$R3="","",'ĐĂNG KÝ'!$A3) | B3: =IF($A3="","",'ĐĂNG KÝ'!$B3) | I3: =IF($A3="","",IFERROR(VLOOKUP($A3,'THÀNH VIÊN'!$A$3:$J$200,5,FALSE),"")) | J3: =IF($A3="","",IFERROR(VLOOKUP($A3,'THÀNH VIÊN'!$A$3:$J$200,4,FALSE),"")) | K3: =IF($A3="","",'ĐĂNG KÝ'!$E3) | L3: =IF($A3="","",'ĐĂNG KÝ'!$F3) | P3: =IF($A3="","",IFERROR(VLOOKUP($A3,'THÀNH VIÊN'!$A$3:$J$200,6,FALSE),"")) | S3: =IF($A3="","",'ĐĂNG KÝ'!$R3)
A4: =IF('ĐĂNG KÝ'!$R4="","",'ĐĂNG KÝ'!$A4) | B4: =IF($A4="","",'ĐĂNG KÝ'!$B4) | I4: =IF($A4="","",IFERROR(VLOOKUP($A4,'THÀNH VIÊN'!$A$3:$J$200,5,FALSE),"")) | J4: =IF($A4="","",IFERROR(VLOOKUP($A4,'THÀNH VIÊN'!$A$3:$J$200,4,FALSE),"")) | K4: =IF($A4="","",'ĐĂNG KÝ'!$E4) | L4: =IF($A4="","",'ĐĂNG KÝ'!$F4) | P4: =IF($A4="","",IFERROR(VLOOKUP($A4,'THÀNH VIÊN'!$A$3:$J$200,6,FALSE),"")) | S4: =IF($A4="","",'ĐĂNG KÝ'!$R4)
A5: =IF('ĐĂNG KÝ'!$R5="","",'ĐĂNG KÝ'!$A5) | B5: =IF($A5="","",'ĐĂNG KÝ'!$B5) | I5: =IF($A5="","",IFERROR(VLOOKUP($A5,'THÀNH VIÊN'!$A$3:$J$200,5,FALSE),"")) | J5: =IF($A5="","",IFERROR(VLOOKUP($A5,'THÀNH VIÊN'!$A$3:$J$200,4,FALSE),"")) | K5: =IF($A5="","",'ĐĂNG KÝ'!$E5) | L5: =IF($A5="","",'ĐĂNG KÝ'!$F5) | P5: =IF($A5="","",IFERROR(VLOOKUP($A5,'THÀNH VIÊN'!$A$3:$J$200,6,FALSE),"")) | S5: =IF($A5="","",'ĐĂNG KÝ'!$R5)
A6: =IF('ĐĂNG KÝ'!$R6="","",'ĐĂNG KÝ'!$A6) | B6: =IF($A6="","",'ĐĂNG KÝ'!$B6) | I6: =IF($A6="","",IFERROR(VLOOKUP($A6,'THÀNH VIÊN'!$A$3:$J$200,5,FALSE),"")) | J6: =IF($A6="","",IFERROR(VLOOKUP($A6,'THÀNH VIÊN'!$A$3:$J$200,4,FALSE),"")) | K6: =IF($A6="","",'ĐĂNG KÝ'!$E6) | L6: =IF($A6="","",'ĐĂNG KÝ'!$F6) | P6: =IF($A6="","",IFERROR(VLOOKUP($A6,'THÀNH VIÊN'!$A$3:$J$200,6,FALSE),"")) | S6: =IF($A6="","",'ĐĂNG KÝ'!$R6)
A7: =IF('ĐĂNG KÝ'!$R7="","",'ĐĂNG KÝ'!$A7) | B7: =IF($A7="","",'ĐĂNG KÝ'!$B7) | I7: =IF($A7="","",IFERROR(VLOOKUP($A7,'THÀNH VIÊN'!$A$3:$J$200,5,FALSE),"")) | J7: =IF($A7="","",IFERROR(VLOOKUP($A7,'THÀNH VIÊN'!$A$3:$J$200,4,FALSE),"")) | K7: =IF($A7="","",'ĐĂNG KÝ'!$E7) | L7: =IF($A7="","",'ĐĂNG KÝ'!$F7) | P7: =IF($A7="","",IFERROR(VLOOKUP($A7,'THÀNH VIÊN'!$A$3:$J$200,6,FALSE),"")) | S7: =IF($A7="","",'ĐĂNG KÝ'!$R7)
A8: =IF('ĐĂNG KÝ'!$R8="","",'ĐĂNG KÝ'!$A8) | B8: =IF($A8="","",'ĐĂNG KÝ'!$B8) | I8: =IF($A8="","",IFERROR(VLOOKUP($A8,'THÀNH VIÊN'!$A$3:$J$200,5,FALSE),"")) | J8: =IF($A8="","",IFERROR(VLOOKUP($A8,'THÀNH VIÊN'!$A$3:$J$200,4,FALSE),"")) | K8: =IF($A8="","",'ĐĂNG KÝ'!$E8) | L8: =IF($A8="","",'ĐĂNG KÝ'!$F8) | P8: =IF($A8="","",IFERROR(VLOOKUP($A8,'THÀNH VIÊN'!$A$3:$J$200,6,FALSE),"")) | S8: =IF($A8="","",'ĐĂNG KÝ'!$R8)
A9: =IF('ĐĂNG KÝ'!$R9="","",'ĐĂNG KÝ'!$A9) | B9: =IF($A9="","",'ĐĂNG KÝ'!$B9) | I9: =IF($A9="","",IFERROR(VLOOKUP($A9,'THÀNH VIÊN'!$A$3:$J$200,5,FALSE),"")) | J9: =IF($A9="","",IFERROR(VLOOKUP($A9,'THÀNH VIÊN'!$A$3:$J$200,4,FALSE),"")) | K9: =IF($A9="","",'ĐĂNG KÝ'!$E9) | L9: =IF($A9="","",'ĐĂNG KÝ'!$F9) | P9: =IF($A9="","",IFERROR(VLOOKUP($A9,'THÀNH VIÊN'!$A$3:$J$200,6,FALSE),"")) | S9: =IF($A9="","",'ĐĂNG KÝ'!$R9)
A10: =IF('ĐĂNG KÝ'!$R10="","",'ĐĂNG KÝ'!$A10) | B10: =IF($A10="","",'ĐĂNG KÝ'!$B10) | I10: =IF($A10="","",IFERROR(VLOOKUP($A10,'THÀNH VIÊN'!$A$3:$J$200,5,FALSE),"")) | J10: =IF($A10="","",IFERROR(VLOOKUP($A10,'THÀNH VIÊN'!$A$3:$J$200,4,FALSE),"")) | K10: =IF($A10="","",'ĐĂNG KÝ'!$E10) | L10: =IF($A10="","",'ĐĂNG KÝ'!$F10) | P10: =IF($A10="","",IFERROR(VLOOKUP($A10,'THÀNH VIÊN'!$A$3:$J$200,6,FALSE),"")) | S10: =IF($A10="","",'ĐĂNG KÝ'!$R10)
A11: =IF('ĐĂNG KÝ'!$R11="","",'ĐĂNG KÝ'!$A11) | B11: =IF($A11="","",'ĐĂNG KÝ'!$B11) | I11: =IF($A11="","",IFERROR(VLOOKUP($A11,'THÀNH VIÊN'!$A$3:$J$200,5,FALSE),"")) | J11: =IF($A11="","",IFERROR(VLOOKUP($A11,'THÀNH VIÊN'!$A$3:$J$200,4,FALSE),"")) | K11: =IF($A11="","",'ĐĂNG KÝ'!$E11) | L11: =IF($A11="","",'ĐĂNG KÝ'!$F11) | P11: =IF($A11="","",IFERROR(VLOOKUP($A11,'THÀNH VIÊN'!$A$3:$J$200,6,FALSE),"")) | S11: =IF($A11="","",'ĐĂNG KÝ'!$R11)
A12: =IF('ĐĂNG KÝ'!$R12="","",'ĐĂNG KÝ'!$A12) | B12: =IF($A12="","",'ĐĂNG KÝ'!$B12) | I12: =IF($A12="","",IFERROR(VLOOKUP($A12,'THÀNH VIÊN'!$A$3:$J$200,5,FALSE),"")) | J12: =IF($A12="","",IFERROR(VLOOKUP($A12,'THÀNH VIÊN'!$A$3:$J$200,4,FALSE),"")) | K12: =IF($A12="","",'ĐĂNG KÝ'!$E12) | L12: =IF($A12="","",'ĐĂNG KÝ'!$F12) | P12: =IF($A12="","",IFERROR(VLOOKUP($A12,'THÀNH VIÊN'!$A$3:$J$200,6,FALSE),"")) | S12: =IF($A12="","",'ĐĂNG KÝ'!$R12)
A13: =IF('ĐĂNG KÝ'!$R13="","",'ĐĂNG KÝ'!$A13) | B13: =IF($A13="","",'ĐĂNG KÝ'!$B13) | I13: =IF($A13="","",IFERROR(VLOOKUP($A13,'THÀNH VIÊN'!$A$3:$J$200,5,FALSE),"")) | J13: =IF($A13="","",IFERROR(VLOOKUP($A13,'THÀNH VIÊN'!$A$3:$J$200,4,FALSE),"")) | K13: =IF($A13="","",'ĐĂNG KÝ'!$E13) | L13: =IF($A13="","",'ĐĂNG KÝ'!$F13) | P13: =IF($A13="","",IFERROR(VLOOKUP($A13,'THÀNH VIÊN'!$A$3:$J$200,6,FALSE),"")) | S13: =IF($A13="","",'ĐĂNG KÝ'!$R13)
A14: =IF('ĐĂNG KÝ'!$R14="","",'ĐĂNG KÝ'!$A14) | B14: =IF($A14="","",'ĐĂNG KÝ'!$B14) | I14: =IF($A14="","",IFERROR(VLOOKUP($A14,'THÀNH VIÊN'!$A$3:$J$200,5,FALSE),"")) | J14: =IF($A14="","",IFERROR(VLOOKUP($A14,'THÀNH VIÊN'!$A$3:$J$200,4,FALSE),"")) | K14: =IF($A14="","",'ĐĂNG KÝ'!$E14) | L14: =IF($A14="","",'ĐĂNG KÝ'!$F14) | P14: =IF($A14="","",IFERROR(VLOOKUP($A14,'THÀNH VIÊN'!$A$3:$J$200,6,FALSE),"")) | S14: =IF($A14="","",'ĐĂNG KÝ'!$R14)
... A40: =IF('ĐĂNG KÝ'!$R40="","",'ĐĂNG KÝ'!$A40) | B40: =IF($A40="","",'ĐĂNG KÝ'!$B40) | I40: =IF($A40="","",IFERROR(VLOOKUP($A40,'THÀNH VIÊN'!$A$3:$J$200,5,FALSE),"")) | J40: =IF($A40="","",IFERROR(VLOOKUP($A40,'THÀNH VIÊN'!$A$3:$J$200,4,FALSE),"")) | K40: =IF($A40="","",'ĐĂNG KÝ'!$E40) | L40: =IF($A40="","",'ĐĂNG KÝ'!$F40) | P40: =IF($A40="","",IFERROR(VLOOKUP($A40,'THÀNH VIÊN'!$A$3:$J$200,6,FALSE),"")) | S40: =IF($A40="","",'ĐĂNG KÝ'!$R40)

Sheet ĐỘI
A1: 🔒 ĐỘI HÌNH (admin) — phân đội Đồng đội 3 / Đồng đội 5
A2: Mã thành viên | B2: Họ tên | C2: Kyu/Dan | D2: Giới tính | E2: Nội dung | F2: Mã đội | G2: Vị trí | H2: Ghi chú
B3: =IF($A3="","",IFERROR(VLOOKUP($A3,'THÀNH VIÊN'!$A$3:$J$200,3,FALSE),"")) | C3: =IF($A3="","",IFERROR(VLOOKUP($A3,'THÀNH VIÊN'!$A$3:$J$200,6,FALSE),"")) | D3: =IF($A3="","",IFERROR(VLOOKUP($A3,'THÀNH VIÊN'!$A$3:$J$200,4,FALSE),""))
B4: =IF($A4="","",IFERROR(VLOOKUP($A4,'THÀNH VIÊN'!$A$3:$J$200,3,FALSE),"")) | C4: =IF($A4="","",IFERROR(VLOOKUP($A4,'THÀNH VIÊN'!$A$3:$J$200,6,FALSE),"")) | D4: =IF($A4="","",IFERROR(VLOOKUP($A4,'THÀNH VIÊN'!$A$3:$J$200,4,FALSE),""))
B5: =IF($A5="","",IFERROR(VLOOKUP($A5,'THÀNH VIÊN'!$A$3:$J$200,3,FALSE),"")) | C5: =IF($A5="","",IFERROR(VLOOKUP($A5,'THÀNH VIÊN'!$A$3:$J$200,6,FALSE),"")) | D5: =IF($A5="","",IFERROR(VLOOKUP($A5,'THÀNH VIÊN'!$A$3:$J$200,4,FALSE),""))
B6: =IF($A6="","",IFERROR(VLOOKUP($A6,'THÀNH VIÊN'!$A$3:$J$200,3,FALSE),"")) | C6: =IF($A6="","",IFERROR(VLOOKUP($A6,'THÀNH VIÊN'!$A$3:$J$200,6,FALSE),"")) | D6: =IF($A6="","",IFERROR(VLOOKUP($A6,'THÀNH VIÊN'!$A$3:$J$200,4,FALSE),""))
B7: =IF($A7="","",IFERROR(VLOOKUP($A7,'THÀNH VIÊN'!$A$3:$J$200,3,FALSE),"")) | C7: =IF($A7="","",IFERROR(VLOOKUP($A7,'THÀNH VIÊN'!$A$3:$J$200,6,FALSE),"")) | D7: =IF($A7="","",IFERROR(VLOOKUP($A7,'THÀNH VIÊN'!$A$3:$J$200,4,FALSE),""))
B8: =IF($A8="","",IFERROR(VLOOKUP($A8,'THÀNH VIÊN'!$A$3:$J$200,3,FALSE),"")) | C8: =IF($A8="","",IFERROR(VLOOKUP($A8,'THÀNH VIÊN'!$A$3:$J$200,6,FALSE),"")) | D8: =IF($A8="","",IFERROR(VLOOKUP($A8,'THÀNH VIÊN'!$A$3:$J$200,4,FALSE),""))
B9: =IF($A9="","",IFERROR(VLOOKUP($A9,'THÀNH VIÊN'!$A$3:$J$200,3,FALSE),"")) | C9: =IF($A9="","",IFERROR(VLOOKUP($A9,'THÀNH VIÊN'!$A$3:$J$200,6,FALSE),"")) | D9: =IF($A9="","",IFERROR(VLOOKUP($A9,'THÀNH VIÊN'!$A$3:$J$200,4,FALSE),""))
B10: =IF($A10="","",IFERROR(VLOOKUP($A10,'THÀNH VIÊN'!$A$3:$J$200,3,FALSE),"")) | C10: =IF($A10="","",IFERROR(VLOOKUP($A10,'THÀNH VIÊN'!$A$3:$J$200,6,FALSE),"")) | D10: =IF($A10="","",IFERROR(VLOOKUP($A10,'THÀNH VIÊN'!$A$3:$J$200,4,FALSE),""))
B11: =IF($A11="","",IFERROR(VLOOKUP($A11,'THÀNH VIÊN'!$A$3:$J$200,3,FALSE),"")) | C11: =IF($A11="","",IFERROR(VLOOKUP($A11,'THÀNH VIÊN'!$A$3:$J$200,6,FALSE),"")) | D11: =IF($A11="","",IFERROR(VLOOKUP($A11,'THÀNH VIÊN'!$A$3:$J$200,4,FALSE),""))
B12: =IF($A12="","",IFERROR(VLOOKUP($A12,'THÀNH VIÊN'!$A$3:$J$200,3,FALSE),"")) | C12: =IF($A12="","",IFERROR(VLOOKUP($A12,'THÀNH VIÊN'!$A$3:$J$200,6,FALSE),"")) | D12: =IF($A12="","",IFERROR(VLOOKUP($A12,'THÀNH VIÊN'!$A$3:$J$200,4,FALSE),""))
B13: =IF($A13="","",IFERROR(VLOOKUP($A13,'THÀNH VIÊN'!$A$3:$J$200,3,FALSE),"")) | C13: =IF($A13="","",IFERROR(VLOOKUP($A13,'THÀNH VIÊN'!$A$3:$J$200,6,FALSE),"")) | D13: =IF($A13="","",IFERROR(VLOOKUP($A13,'THÀNH VIÊN'!$A$3:$J$200,4,FALSE),""))
B14: =IF($A14="","",IFERROR(VLOOKUP($A14,'THÀNH VIÊN'!$A$3:$J$200,3,FALSE),"")) | C14: =IF($A14="","",IFERROR(VLOOKUP($A14,'THÀNH VIÊN'!$A$3:$J$200,6,FALSE),"")) | D14: =IF($A14="","",IFERROR(VLOOKUP($A14,'THÀNH VIÊN'!$A$3:$J$200,4,FALSE),""))
... B42: =IF($A42="","",IFERROR(VLOOKUP($A42,'THÀNH VIÊN'!$A$3:$J$200,3,FALSE),"")) | C42: =IF($A42="","",IFERROR(VLOOKUP($A42,'THÀNH VIÊN'!$A$3:$J$200,6,FALSE),"")) | D42: =IF($A42="","",IFERROR(VLOOKUP($A42,'THÀNH VIÊN'!$A$3:$J$200,4,FALSE),""))
A45: TỔNG HỢP
A46: Đồng đội 3 | B46: =COUNTIF($E$3:$E$42,"Đồng đội 3") | D46: SKJ 01 | E46: =COUNTIF($F$3:$F$42,"SKJ 01")
A47: Đồng đội 5 | B47: =COUNTIF($E$3:$E$42,"Đồng đội 5") | D47: SKJ 02 | E47: =COUNTIF($F$3:$F$42,"SKJ 02")
D48: SKJ 03 | E48: =COUNTIF($F$3:$F$42,"SKJ 03")
D49: SKJ 04 | E49: =COUNTIF($F$3:$F$42,"SKJ 04")
D50: SKJ 05 | E50: =COUNTIF($F$3:$F$42,"SKJ 05")
D51: SKJ 06 | E51: =COUNTIF($F$3:$F$42,"SKJ 06")

Sheet Provider
A1: 🔒 Provider — danh mục nhà cung cấp theo scope (admin cập nhật; thành viên chọn mã ở tab ĐĂNG KÝ)
A3: VÉ MÁY BAY (FL) · mã FL-###
A4: Mã | B4: Scope | C4: Nhà cung cấp | D4: Liên hệ | E4: SĐT | F4: Email | G4: Tuyến / Chặng | H4: Chiều | I4: Hãng / ĐV | J4: Ngày giờ | K4: Điểm đi | L4: Điểm đến | M4: Điều kiện | N4: Đơn giá/người | O4: Phí DV | P4: Tổng/người | Q4: Hiệu lực đến | R4: Trạng thái | S4: Ghi chú
A5: FL-001 | B5: Vé máy bay | P5: =IF($N5="","",$N5+IF($O5="",0,$O5)) | R5: Còn hiệu lực
A6: FL-002 | B6: Vé máy bay | P6: =IF($N6="","",$N6+IF($O6="",0,$O6)) | R6: Còn hiệu lực
A7: FL-003 | B7: Vé máy bay | P7: =IF($N7="","",$N7+IF($O7="",0,$O7)) | R7: Còn hiệu lực
A8: FL-004 | B8: Vé máy bay | P8: =IF($N8="","",$N8+IF($O8="",0,$O8)) | R8: Còn hiệu lực
A9: FL-005 | B9: Vé máy bay | P9: =IF($N9="","",$N9+IF($O9="",0,$O9)) | R9: Còn hiệu lực
A10: FL-006 | B10: Vé máy bay | P10: =IF($N10="","",$N10+IF($O10="",0,$O10)) | R10: Còn hiệu lực
A11: FL-007 | B11: Vé máy bay | P11: =IF($N11="","",$N11+IF($O11="",0,$O11)) | R11: Còn hiệu lực
A12: FL-008 | B12: Vé máy bay | P12: =IF($N12="","",$N12+IF($O12="",0,$O12)) | R12: Còn hiệu lực
A13: FL-009 | B13: Vé máy bay | P13: =IF($N13="","",$N13+IF($O13="",0,$O13)) | R13: Còn hiệu lực
A14: FL-010 | B14: Vé máy bay | P14: =IF($N14="","",$N14+IF($O14="",0,$O14)) | R14: Còn hiệu lực
A16: XE / DI CHUYỂN (BUS) · mã BUS-###
A17: Mã | B17: Scope | C17: Nhà cung cấp | D17: Liên hệ | E17: SĐT | F17: Email | G17: Tuyến / Chặng | H17: Chiều | I17: Hãng / ĐV | J17: Ngày giờ | K17: Điểm đi | L17: Điểm đến | M17: Điều kiện | N17: Đơn giá/người | O17: Phí DV | P17: Tổng/người | Q17: Hiệu lực đến | R17: Trạng thái | S17: Ghi chú
A18: BUS-001 | B18: Xe | C18: Noi Bai taxi | E18: 0888.100.100 | G18: Nội Bài ↔ Tam Chúc | K18: Hà Nội | L18: Tam Chúc | N18: 750000 | P18: =IF($N18="","",$N18+IF($O18="",0,$O18)) | R18: Còn hiệu lực | S18: 3–4 người gồm hành lý · 2–2.5 giờ
A19: BUS-002 | B19: Xe | C19: Bus 16 chỗ | E19: 0904409090 | G19: Nội Bài ↔ Tam Chúc | K19: Hà Nội | L19: Tam Chúc | N19: 1800000 | P19: =IF($N19="","",$N19+IF($O19="",0,$O19)) | R19: Còn hiệu lực | S19: tối đa 9 người kèm hành lý
A20: BUS-003 | B20: Xe | C20: Bus 29 chỗ | E20: 0904409090 | G20: Nội Bài ↔ Tam Chúc | K20: Hà Nội | L20: Tam Chúc | N20: 2300000 | P20: =IF($N20="","",$N20+IF($O20="",0,$O20)) | R20: Còn hiệu lực | S20: có khoang hành lý riêng
A21: BUS-004 | B21: Xe | C21: Bus 35 chỗ | E21: 0904409090 | G21: Nội Bài ↔ Tam Chúc | K21: Hà Nội | L21: Tam Chúc | N21: 2800000 | P21: =IF($N21="","",$N21+IF($O21="",0,$O21)) | R21: Còn hiệu lực
A22: BUS-005 | B22: Xe | C22: Bus 45 chỗ | E22: 0904409090 | G22: Nội Bài ↔ Tam Chúc | K22: Hà Nội | L22: Tam Chúc | N22: 3500000 | P22: =IF($N22="","",$N22+IF($O22="",0,$O22)) | R22: Còn hiệu lực
A23: BUS-006 | B23: Xe | P23: =IF($N23="","",$N23+IF($O23="",0,$O23)) | R23: Còn hiệu lực
A24: BUS-007 | B24: Xe | P24: =IF($N24="","",$N24+IF($O24="",0,$O24)) | R24: Còn hiệu lực
A25: BUS-008 | B25: Xe | P25: =IF($N25="","",$N25+IF($O25="",0,$O25)) | R25: Còn hiệu lực
A26: BUS-009 | B26: Xe | P26: =IF($N26="","",$N26+IF($O26="",0,$O26)) | R26: Còn hiệu lực
A27: BUS-010 | B27: Xe | P27: =IF($N27="","",$N27+IF($O27="",0,$O27)) | R27: Còn hiệu lực
A29: KHÁCH SẠN HÀ NỘI (HTL) · mã HTL-###
A30: Mã | B30: Scope | C30: Nhà cung cấp | D30: Liên hệ | E30: SĐT | F30: Email | G30: Tuyến / Chặng | H30: Chiều | I30: Hãng / ĐV | J30: Ngày giờ | K30: Điểm đi | L30: Điểm đến | M30: Điều kiện | N30: Đơn giá/người | O30: Phí DV | P30: Tổng/người | Q30: Hiệu lực đến | R30: Trạng thái | S30: Ghi chú
A31: HTL-001 | B31: Khách sạn Hà Nội | P31: =IF($N31="","",$N31+IF($O31="",0,$O31)) | R31: Còn hiệu lực
A32: HTL-002 | B32: Khách sạn Hà Nội | P32: =IF($N32="","",$N32+IF($O32="",0,$O32)) | R32: Còn hiệu lực
A33: HTL-003 | B33: Khách sạn Hà Nội | P33: =IF($N33="","",$N33+IF($O33="",0,$O33)) | R33: Còn hiệu lực
A34: HTL-004 | B34: Khách sạn Hà Nội | P34: =IF($N34="","",$N34+IF($O34="",0,$O34)) | R34: Còn hiệu lực
A35: HTL-005 | B35: Khách sạn Hà Nội | P35: =IF($N35="","",$N35+IF($O35="",0,$O35)) | R35: Còn hiệu lực
A36: HTL-006 | B36: Khách sạn Hà Nội | P36: =IF($N36="","",$N36+IF($O36="",0,$O36)) | R36: Còn hiệu lực
A37: HTL-007 | B37: Khách sạn Hà Nội | P37: =IF($N37="","",$N37+IF($O37="",0,$O37)) | R37: Còn hiệu lực
A38: HTL-008 | B38: Khách sạn Hà Nội | P38: =IF($N38="","",$N38+IF($O38="",0,$O38)) | R38: Còn hiệu lực
A39: HTL-009 | B39: Khách sạn Hà Nội | P39: =IF($N39="","",$N39+IF($O39="",0,$O39)) | R39: Còn hiệu lực
A40: HTL-010 | B40: Khách sạn Hà Nội | P40: =IF($N40="","",$N40+IF($O40="",0,$O40)) | R40: Còn hiệu lực

Sheet CHI PHÍ
A1: CHI PHÍ
A2: ⏳ Sẽ hoàn thiện ở Phase 5
A3: Mã thành viên | B3: Họ tên | C3: Gói VKF | D3: Lệ phí thi | E3: Đêm thêm NB | F3: Vé MB | G3: Di chuyển | H3: KS HN | I3: Ăn HN | J3: Đi lại HN | K3: Zekken | L3: Bảo hiểm | M3: Khác | N3: Tổng | O3: Đã TT | P3: Còn lại

Sheet LỊCH TRÌNH
A1: LỊCH TRÌNH
A2: ⏳ Sẽ hoàn thiện ở Phase 6
A3: Ngày | B3: Thứ | C3: Từ | D3: Đến | E3: Hoạt động | F3: Địa điểm | G3: PIC | H3: Ghi chú

Sheet TỔNG QUAN
A1: TỔNG QUAN
A2: ⏳ Sẽ hoàn thiện ở Phase 7
A3: Chỉ số | B3: Giá trị | C3: Ghi chú
